2022-06-06 17:15:01,840 INFO: Microblog startup [in /home/ogbonna/projects/microblog/app/__init__.py:33]
2022-06-06 17:15:35,099 ERROR: Exception on /edit_profile [POST] [in /home/ogbonna/projects/microblog/venv/lib/python3.8/site-packages/flask/app.py:1455]
Traceback (most recent call last):
  File "/home/ogbonna/projects/microblog/venv/lib/python3.8/site-packages/sqlalchemy/engine/base.py", line 1819, in _execute_context
    self.dialect.do_execute(
  File "/home/ogbonna/projects/microblog/venv/lib/python3.8/site-packages/sqlalchemy/engine/default.py", line 732, in do_execute
    cursor.execute(statement, parameters)
sqlite3.IntegrityError: UNIQUE constraint failed: user.username

The above exception was the direct cause of the following exception:

Traceback (most recent call last):
  File "/home/ogbonna/projects/microblog/venv/lib/python3.8/site-packages/flask/app.py", line 2077, in wsgi_app
    response = self.full_dispatch_request()
  File "/home/ogbonna/projects/microblog/venv/lib/python3.8/site-packages/flask/app.py", line 1525, in full_dispatch_request
    rv = self.handle_user_exception(e)
  File "/home/ogbonna/projects/microblog/venv/lib/python3.8/site-packages/flask/app.py", line 1523, in full_dispatch_request
    rv = self.dispatch_request()
  File "/home/ogbonna/projects/microblog/venv/lib/python3.8/site-packages/flask/app.py", line 1509, in dispatch_request
    return self.ensure_sync(self.view_functions[rule.endpoint])(**req.view_args)
  File "/home/ogbonna/projects/microblog/venv/lib/python3.8/site-packages/flask_login/utils.py", line 303, in decorated_view
    return current_app.ensure_sync(func)(*args, **kwargs)
  File "/home/ogbonna/projects/microblog/app/routes.py", line 100, in edit_profile
    db.session.commit()
  File "<string>", line 2, in commit
  File "/home/ogbonna/projects/microblog/venv/lib/python3.8/site-packages/sqlalchemy/orm/session.py", line 1435, in commit
    self._transaction.commit(_to_root=self.future)
  File "/home/ogbonna/projects/microblog/venv/lib/python3.8/site-packages/sqlalchemy/orm/session.py", line 829, in commit
    self._prepare_impl()
  File "/home/ogbonna/projects/microblog/venv/lib/python3.8/site-packages/sqlalchemy/orm/session.py", line 808, in _prepare_impl
    self.session.flush()
  File "/home/ogbonna/projects/microblog/venv/lib/python3.8/site-packages/sqlalchemy/orm/session.py", line 3367, in flush
    self._flush(objects)
  File "/home/ogbonna/projects/microblog/venv/lib/python3.8/site-packages/sqlalchemy/orm/session.py", line 3507, in _flush
    transaction.rollback(_capture_exception=True)
  File "/home/ogbonna/projects/microblog/venv/lib/python3.8/site-packages/sqlalchemy/util/langhelpers.py", line 70, in __exit__
    compat.raise_(
  File "/home/ogbonna/projects/microblog/venv/lib/python3.8/site-packages/sqlalchemy/util/compat.py", line 207, in raise_
    raise exception
  File "/home/ogbonna/projects/microblog/venv/lib/python3.8/site-packages/sqlalchemy/orm/session.py", line 3467, in _flush
    flush_context.execute()
  File "/home/ogbonna/projects/microblog/venv/lib/python3.8/site-packages/sqlalchemy/orm/unitofwork.py", line 456, in execute
    rec.execute(self)
  File "/home/ogbonna/projects/microblog/venv/lib/python3.8/site-packages/sqlalchemy/orm/unitofwork.py", line 630, in execute
    util.preloaded.orm_persistence.save_obj(
  File "/home/ogbonna/projects/microblog/venv/lib/python3.8/site-packages/sqlalchemy/orm/persistence.py", line 237, in save_obj
    _emit_update_statements(
  File "/home/ogbonna/projects/microblog/venv/lib/python3.8/site-packages/sqlalchemy/orm/persistence.py", line 1001, in _emit_update_statements
    c = connection._execute_20(
  File "/home/ogbonna/projects/microblog/venv/lib/python3.8/site-packages/sqlalchemy/engine/base.py", line 1631, in _execute_20
    return meth(self, args_10style, kwargs_10style, execution_options)
  File "/home/ogbonna/projects/microblog/venv/lib/python3.8/site-packages/sqlalchemy/sql/elements.py", line 325, in _execute_on_connection
    return connection._execute_clauseelement(
  File "/home/ogbonna/projects/microblog/venv/lib/python3.8/site-packages/sqlalchemy/engine/base.py", line 1498, in _execute_clauseelement
    ret = self._execute_context(
  File "/home/ogbonna/projects/microblog/venv/lib/python3.8/site-packages/sqlalchemy/engine/base.py", line 1862, in _execute_context
    self._handle_dbapi_exception(
  File "/home/ogbonna/projects/microblog/venv/lib/python3.8/site-packages/sqlalchemy/engine/base.py", line 2043, in _handle_dbapi_exception
    util.raise_(
  File "/home/ogbonna/projects/microblog/venv/lib/python3.8/site-packages/sqlalchemy/util/compat.py", line 207, in raise_
    raise exception
  File "/home/ogbonna/projects/microblog/venv/lib/python3.8/site-packages/sqlalchemy/engine/base.py", line 1819, in _execute_context
    self.dialect.do_execute(
  File "/home/ogbonna/projects/microblog/venv/lib/python3.8/site-packages/sqlalchemy/engine/default.py", line 732, in do_execute
    cursor.execute(statement, parameters)
sqlalchemy.exc.IntegrityError: (sqlite3.IntegrityError) UNIQUE constraint failed: user.username
[SQL: UPDATE user SET username=?, about_me=? WHERE user.id = ?]
[parameters: ('susan', 'Just another day with another story.', 2)]
(Background on this error at: https://sqlalche.me/e/14/gkpj)
2022-06-06 18:10:23,469 INFO: Microblog startup [in /home/ogbonna/projects/microblog/app/__init__.py:33]
2022-06-06 18:10:46,077 ERROR: Exception on /edit_profile [POST] [in /home/ogbonna/projects/microblog/venv/lib/python3.8/site-packages/flask/app.py:1455]
Traceback (most recent call last):
  File "/home/ogbonna/projects/microblog/venv/lib/python3.8/site-packages/flask/app.py", line 2077, in wsgi_app
    response = self.full_dispatch_request()
  File "/home/ogbonna/projects/microblog/venv/lib/python3.8/site-packages/flask/app.py", line 1525, in full_dispatch_request
    rv = self.handle_user_exception(e)
  File "/home/ogbonna/projects/microblog/venv/lib/python3.8/site-packages/flask/app.py", line 1523, in full_dispatch_request
    rv = self.dispatch_request()
  File "/home/ogbonna/projects/microblog/venv/lib/python3.8/site-packages/flask/app.py", line 1509, in dispatch_request
    return self.ensure_sync(self.view_functions[rule.endpoint])(**req.view_args)
  File "/home/ogbonna/projects/microblog/venv/lib/python3.8/site-packages/flask_login/utils.py", line 303, in decorated_view
    return current_app.ensure_sync(func)(*args, **kwargs)
  File "/home/ogbonna/projects/microblog/app/routes.py", line 97, in edit_profile
    if form.validate_on_submit():
  File "/home/ogbonna/projects/microblog/venv/lib/python3.8/site-packages/flask_wtf/form.py", line 86, in validate_on_submit
    return self.is_submitted() and self.validate()
  File "/home/ogbonna/projects/microblog/venv/lib/python3.8/site-packages/wtforms/form.py", line 329, in validate
    return super().validate(extra)
  File "/home/ogbonna/projects/microblog/venv/lib/python3.8/site-packages/wtforms/form.py", line 146, in validate
    if not field.validate(self, extra):
  File "/home/ogbonna/projects/microblog/venv/lib/python3.8/site-packages/wtforms/fields/core.py", line 242, in validate
    stop_validation = self._run_validation_chain(form, chain)
  File "/home/ogbonna/projects/microblog/venv/lib/python3.8/site-packages/wtforms/fields/core.py", line 262, in _run_validation_chain
    validator(form, self)
  File "/home/ogbonna/projects/microblog/app/forms.py", line 44, in validate_username
    raise ValidationError('Please use a different username.')
NameError: name 'ValidationError' is not defined
2022-06-06 18:17:11,804 INFO: Microblog startup [in /home/ogbonna/projects/microblog/app/__init__.py:33]
2022-06-06 18:17:27,984 ERROR: Exception on /edit_profile [POST] [in /home/ogbonna/projects/microblog/venv/lib/python3.8/site-packages/flask/app.py:1455]
Traceback (most recent call last):
  File "/home/ogbonna/projects/microblog/venv/lib/python3.8/site-packages/flask/app.py", line 2077, in wsgi_app
    response = self.full_dispatch_request()
  File "/home/ogbonna/projects/microblog/venv/lib/python3.8/site-packages/flask/app.py", line 1525, in full_dispatch_request
    rv = self.handle_user_exception(e)
  File "/home/ogbonna/projects/microblog/venv/lib/python3.8/site-packages/flask/app.py", line 1523, in full_dispatch_request
    rv = self.dispatch_request()
  File "/home/ogbonna/projects/microblog/venv/lib/python3.8/site-packages/flask/app.py", line 1509, in dispatch_request
    return self.ensure_sync(self.view_functions[rule.endpoint])(**req.view_args)
  File "/home/ogbonna/projects/microblog/venv/lib/python3.8/site-packages/flask_login/utils.py", line 303, in decorated_view
    return current_app.ensure_sync(func)(*args, **kwargs)
  File "/home/ogbonna/projects/microblog/app/routes.py", line 97, in edit_profile
    if form.validate_on_submit():
  File "/home/ogbonna/projects/microblog/venv/lib/python3.8/site-packages/flask_wtf/form.py", line 86, in validate_on_submit
    return self.is_submitted() and self.validate()
  File "/home/ogbonna/projects/microblog/venv/lib/python3.8/site-packages/wtforms/form.py", line 329, in validate
    return super().validate(extra)
  File "/home/ogbonna/projects/microblog/venv/lib/python3.8/site-packages/wtforms/form.py", line 146, in validate
    if not field.validate(self, extra):
  File "/home/ogbonna/projects/microblog/venv/lib/python3.8/site-packages/wtforms/fields/core.py", line 242, in validate
    stop_validation = self._run_validation_chain(form, chain)
  File "/home/ogbonna/projects/microblog/venv/lib/python3.8/site-packages/wtforms/fields/core.py", line 262, in _run_validation_chain
    validator(form, self)
  File "/home/ogbonna/projects/microblog/app/forms.py", line 44, in validate_username
    raise ValidationError('Please use a different username.')
NameError: name 'ValidationError' is not defined
2022-06-11 14:06:17,355 INFO: Microblog startup [in /home/ogbonna/projects/microblog/app/__init__.py:33]
