2022-06-11 14:06:40,436 ERROR: Exception on /edit_profile [POST] [in /home/ogbonna/projects/microblog/venv/lib/python3.8/site-packages/flask/app.py:1455]
Traceback (most recent call last):
  File "/home/ogbonna/projects/microblog/venv/lib/python3.8/site-packages/flask/app.py", line 2077, in wsgi_app
    response = self.full_dispatch_request()
  File "/home/ogbonna/projects/microblog/venv/lib/python3.8/site-packages/flask/app.py", line 1525, in full_dispatch_request
    rv = self.handle_user_exception(e)
  File "/home/ogbonna/projects/microblog/venv/lib/python3.8/site-packages/flask/app.py", line 1523, in full_dispatch_request
    rv = self.dispatch_request()
  File "/home/ogbonna/projects/microblog/venv/lib/python3.8/site-packages/flask/app.py", line 1509, in dispatch_request
    return self.ensure_sync(self.view_functions[rule.endpoint])(**req.view_args)
  File "/home/ogbonna/projects/microblog/venv/lib/python3.8/site-packages/flask_login/utils.py", line 303, in decorated_view
    return current_app.ensure_sync(func)(*args, **kwargs)
  File "/home/ogbonna/projects/microblog/app/routes.py", line 97, in edit_profile
    if form.validate_on_submit():
  File "/home/ogbonna/projects/microblog/venv/lib/python3.8/site-packages/flask_wtf/form.py", line 86, in validate_on_submit
    return self.is_submitted() and self.validate()
  File "/home/ogbonna/projects/microblog/venv/lib/python3.8/site-packages/wtforms/form.py", line 329, in validate
    return super().validate(extra)
  File "/home/ogbonna/projects/microblog/venv/lib/python3.8/site-packages/wtforms/form.py", line 146, in validate
    if not field.validate(self, extra):
  File "/home/ogbonna/projects/microblog/venv/lib/python3.8/site-packages/wtforms/fields/core.py", line 242, in validate
    stop_validation = self._run_validation_chain(form, chain)
  File "/home/ogbonna/projects/microblog/venv/lib/python3.8/site-packages/wtforms/fields/core.py", line 262, in _run_validation_chain
    validator(form, self)
  File "/home/ogbonna/projects/microblog/app/forms.py", line 44, in validate_username
    raise ValidationError('Please use a different username.')
NameError: name 'ValidationError' is not defined
2022-06-11 14:12:08,644 ERROR: Exception on /edit_profile [POST] [in /home/ogbonna/projects/microblog/venv/lib/python3.8/site-packages/flask/app.py:1455]
Traceback (most recent call last):
  File "/home/ogbonna/projects/microblog/venv/lib/python3.8/site-packages/flask/app.py", line 2077, in wsgi_app
    response = self.full_dispatch_request()
  File "/home/ogbonna/projects/microblog/venv/lib/python3.8/site-packages/flask/app.py", line 1525, in full_dispatch_request
    rv = self.handle_user_exception(e)
  File "/home/ogbonna/projects/microblog/venv/lib/python3.8/site-packages/flask/app.py", line 1523, in full_dispatch_request
    rv = self.dispatch_request()
  File "/home/ogbonna/projects/microblog/venv/lib/python3.8/site-packages/flask/app.py", line 1509, in dispatch_request
    return self.ensure_sync(self.view_functions[rule.endpoint])(**req.view_args)
  File "/home/ogbonna/projects/microblog/venv/lib/python3.8/site-packages/flask_login/utils.py", line 303, in decorated_view
    return current_app.ensure_sync(func)(*args, **kwargs)
  File "/home/ogbonna/projects/microblog/app/routes.py", line 97, in edit_profile
    if form.validate_on_submit():
  File "/home/ogbonna/projects/microblog/venv/lib/python3.8/site-packages/flask_wtf/form.py", line 86, in validate_on_submit
    return self.is_submitted() and self.validate()
  File "/home/ogbonna/projects/microblog/venv/lib/python3.8/site-packages/wtforms/form.py", line 329, in validate
    return super().validate(extra)
  File "/home/ogbonna/projects/microblog/venv/lib/python3.8/site-packages/wtforms/form.py", line 146, in validate
    if not field.validate(self, extra):
  File "/home/ogbonna/projects/microblog/venv/lib/python3.8/site-packages/wtforms/fields/core.py", line 242, in validate
    stop_validation = self._run_validation_chain(form, chain)
  File "/home/ogbonna/projects/microblog/venv/lib/python3.8/site-packages/wtforms/fields/core.py", line 262, in _run_validation_chain
    validator(form, self)
  File "/home/ogbonna/projects/microblog/app/forms.py", line 44, in validate_username
    raise ValidationError('Please use a different username.')
NameError: name 'ValidationError' is not defined
2022-06-11 14:17:18,773 INFO: Microblog startup [in /home/ogbonna/projects/microblog/app/__init__.py:33]
2022-06-12 09:05:41,514 INFO: Microblog startup [in /home/ogbonna/projects/microblog/app/__init__.py:33]
2022-06-12 09:13:31,513 INFO: Microblog startup [in /home/ogbonna/projects/microblog/app/__init__.py:33]
2022-06-13 10:28:01,256 INFO: Microblog startup [in /home/ogbonna/projects/microblog/app/__init__.py:33]
2022-06-13 11:16:40,551 INFO: Microblog startup [in /home/ogbonna/projects/microblog/app/__init__.py:33]
2022-06-16 01:19:08,537 INFO: Microblog startup [in /home/ogbonna/projects/microblog/app/__init__.py:33]
2022-06-16 02:16:22,040 INFO: Microblog startup [in /home/ogbonna/projects/microblog/app/__init__.py:33]
2022-06-16 02:20:10,567 INFO: Microblog startup [in /home/ogbonna/projects/microblog/app/__init__.py:33]
2022-06-16 05:10:47,861 INFO: Microblog startup [in /home/ogbonna/projects/microblog/app/__init__.py:45]
2022-06-16 05:11:28,491 INFO: Microblog startup [in /home/ogbonna/projects/microblog/app/__init__.py:45]
